Workbook

Sheet Solar Availability and Gener GR
A1: Hr | B1: Month | C1: Solar_Availability_kW/m^2 | D1: % OF max solar availability (in July 14th) | E1: Area (m2) | F1: Generated from Pv kwh per household | G1: Generated kwh for 4.3 million households (2050) | H1: Generated kwh for 0.86 million households (2030) | I1: Generated kwh for 1.72 million households (2035) | J1: Generated kwh for 2.58 million households (2035) | K1: Generated kwh for 3.44 million households (2035)
A2: 1 | B2: Jan | C2: 0 | D2: 0 | E2: =1*(4000/200) -> 20 | F2: =E2*C2*0.18 -> 0 | G2: =F2*4300000 -> 0 | H2: =(4300000*5/25)*F2 -> 0 | I2: =(4300000*10/25)*F2 -> 0 | J2: =F2*2580000 -> 0 | K2: =F2*3440000 -> 0
A3: 2 | B3: Jan | C3: 0 | D3: 0 | E3: =1*(4000/200) -> 20 | F3: =E3*C3*0.18 -> 0 | G3: =F3*4300000 -> 0 | H3: =(4300000*5/25)*F3 -> 0 | I3: =(4300000*10/25)*F3 -> 0 | J3: =F3*2580000 -> 0 | K3: =F3*3440000 -> 0
A4: 3 | B4: Jan | C4: 0 | D4: 0 | E4: =1*(4000/200) -> 20 | F4: =E4*C4*0.18 -> 0 | G4: =F4*4300000 -> 0 | H4: =(4300000*5/25)*F4 -> 0 | I4: =(4300000*10/25)*F4 -> 0 | J4: =F4*2580000 -> 0 | K4: =F4*3440000 -> 0
A5: 4 | B5: Jan | C5: 0 | D5: 0 | E5: =1*(4000/200) -> 20 | F5: =E5*C5*0.18 -> 0 | G5: =F5*4300000 -> 0 | H5: =(4300000*5/25)*F5 -> 0 | I5: =(4300000*10/25)*F5 -> 0 | J5: =F5*2580000 -> 0 | K5: =F5*3440000 -> 0
A6: 5 | B6: Jan | C6: 0 | D6: 0 | E6: =1*(4000/200) -> 20 | F6: =E6*C6*0.18 -> 0 | G6: =F6*4300000 -> 0 | H6: =(4300000*5/25)*F6 -> 0 | I6: =(4300000*10/25)*F6 -> 0 | J6: =F6*2580000 -> 0 | K6: =F6*3440000 -> 0
A7: 6 | B7: Jan | C7: 0 | D7: 0 | E7: =1*(4000/200) -> 20 | F7: =E7*C7*0.18 -> 0 | G7: =F7*4300000 -> 0 | H7: =(4300000*5/25)*F7 -> 0 | I7: =(4300000*10/25)*F7 -> 0 | J7: =F7*2580000 -> 0 | K7: =F7*3440000 -> 0
A8: 7 | B8: Jan | C8: 0.01 | D8: 1.1012385 | E8: =1*(4000/200) -> 20 | F8: =E8*C8*0.18 -> 0.036 | G8: =F8*4300000 -> 154800 | H8: =(4300000*5/25)*F8 -> 30960 | I8: =(4300000*10/25)*F8 -> 61920 | J8: =F8*2580000 -> 92880 | K8: =F8*3440000 -> 123840
A9: 8 | B9: Jan | C9: 0.02 | D9: 2.202477 | E9: =1*(4000/200) -> 20 | F9: =E9*C9*0.18 -> 0.072 | G9: =F9*4300000 -> 309600 | H9: =(4300000*5/25)*F9 -> 61920 | I9: =(4300000*10/25)*F9 -> 123840 | J9: =F9*2580000 -> 185760 | K9: =F9*3440000 -> 247680
A10: 9 | B10: Jan | C10: 0.03 | D10: 3.3037156 | E10: =1*(4000/200) -> 20 | F10: =E10*C10*0.18 -> 0.108 | G10: =F10*4300000 -> 464400 | H10: =(4300000*5/25)*F10 -> 92880 | I10: =(4300000*10/25)*F10 -> 185760 | J10: =F10*2580000 -> 278640 | K10: =F10*3440000 -> 371520
A11: 10 | B11: Jan | C11: 0.049493308 | D11: 5.4503938 | E11: =1*(4000/200) -> 20 | F11: =E11*C11*0.18 -> 0.17817591 | G11: =F11*4300000 -> 766156.41 | H11: =(4300000*5/25)*F11 -> 153231.28 | I11: =(4300000*10/25)*F11 -> 306462.57 | J11: =F11*2580000 -> 459693.85 | K11: =F11*3440000 -> 612925.13
A12: 11 | B12: Jan | C12: 0.16905917 | D12: 18.617447 | E12: =1*(4000/200) -> 20 | F12: =E12*C12*0.18 -> 0.60861302 | G12: =F12*4300000 -> 2617036 | H12: =(4300000*5/25)*F12 -> 523407.19 | I12: =(4300000*10/25)*F12 -> 1046814.4 | J12: =F12*2580000 -> 1570221.6 | K12: =F12*3440000 -> 2093628.8
A13: 12 | B13: Jan | C13: 0.299 | D13: 32.927032 | E13: =1*(4000/200) -> 20 | F13: =E13*C13*0.18 -> 1.0764 | G13: =F13*4300000 -> 4628520 | H13: =(4300000*5/25)*F13 -> 925704 | I13: =(4300000*10/25)*F13 -> 1851408 | J13: =F13*2580000 -> 2777112 | K13: =F13*3440000 -> 3702816
... A44: 19 | B44: Feb | C44: 0.038 | D44: 4.1847064 | E44: =1*(4000/200) -> 20 | F44: =E44*C44*0.18 -> 0.1368 | G44: =F44*4300000 -> 588240 | H44: =(4300000*5/25)*F44 -> 117648 | I44: =(4300000*10/25)*F44 -> 235296 | J44: =F44*2580000 -> 352944 | K44: =F44*3440000 -> 470592
A45: 20 | B45: Feb | D45: 0 | E45: =1*(4000/200) -> 20 | F45: =E45*C45*0.18 -> 0 | G45: =F45*4300000 -> 0 | H45: =(4300000*5/25)*F45 -> 0 | I45: =(4300000*10/25)*F45 -> 0 | J45: =F45*2580000 -> 0 | K45: =F45*3440000 -> 0
A46: 21 | B46: Feb | D46: 0 | E46: =1*(4000/200) -> 20 | F46: =E46*C46*0.18 -> 0 | G46: =F46*4300000 -> 0 | H46: =(4300000*5/25)*F46 -> 0 | I46: =(4300000*10/25)*F46 -> 0 | J46: =F46*2580000 -> 0 | K46: =F46*3440000 -> 0
A47: 22 | B47: Feb | D47: 0 | E47: =1*(4000/200) -> 20 | F47: =E47*C47*0.18 -> 0 | G47: =F47*4300000 -> 0 | H47: =(4300000*5/25)*F47 -> 0 | I47: =(4300000*10/25)*F47 -> 0 | J47: =F47*2580000 -> 0 | K47: =F47*3440000 -> 0
A48: 23 | B48: Feb | D48: 0 | E48: =1*(4000/200) -> 20 | F48: =E48*C48*0.18 -> 0 | G48: =F48*4300000 -> 0 | H48: =(4300000*5/25)*F48 -> 0 | I48: =(4300000*10/25)*F48 -> 0 | J48: =F48*2580000 -> 0 | K48: =F48*3440000 -> 0
A49: 24 | B49: Feb | D49: 0 | E49: =1*(4000/200) -> 20 | F49: =E49*C49*0.18 -> 0 | G49: =F49*4300000 -> 0 | H49: =(4300000*5/25)*F49 -> 0 | I49: =(4300000*10/25)*F49 -> 0 | J49: =F49*2580000 -> 0 | K49: =F49*3440000 -> 0
A50: 1 | B50: March | D50: 0 | E50: =1*(4000/200) -> 20 | F50: =E50*C50*0.18 -> 0 | G50: =F50*4300000 -> 0 | H50: =(4300000*5/25)*F50 -> 0 | I50: =(4300000*10/25)*F50 -> 0 | J50: =F50*2580000 -> 0 | K50: =F50*3440000 -> 0
A51: 2 | B51: March | D51: 0 | E51: =1*(4000/200) -> 20 | F51: =E51*C51*0.18 -> 0 | G51: =F51*4300000 -> 0 | H51: =(4300000*5/25)*F51 -> 0 | I51: =(4300000*10/25)*F51 -> 0 | J51: =F51*2580000 -> 0 | K51: =F51*3440000 -> 0
A52: 3 | B52: March | D52: 0 | E52: =1*(4000/200) -> 20 | F52: =E52*C52*0.18 -> 0 | G52: =F52*4300000 -> 0 | H52: =(4300000*5/25)*F52 -> 0 | I52: =(4300000*10/25)*F52 -> 0 | J52: =F52*2580000 -> 0 | K52: =F52*3440000 -> 0
A53: 4 | B53: March | D53: 0 | E53: =1*(4000/200) -> 20 | F53: =E53*C53*0.18 -> 0 | G53: =F53*4300000 -> 0 | H53: =(4300000*5/25)*F53 -> 0 | I53: =(4300000*10/25)*F53 -> 0 | J53: =F53*2580000 -> 0 | K53: =F53*3440000 -> 0
A54: 5 | B54: March | D54: 0 | E54: =1*(4000/200) -> 20 | F54: =E54*C54*0.18 -> 0 | G54: =F54*4300000 -> 0 | H54: =(4300000*5/25)*F54 -> 0 | I54: =(4300000*10/25)*F54 -> 0 | J54: =F54*2580000 -> 0 | K54: =F54*3440000 -> 0
A55: 6 | B55: March | D55: 0 | E55: =1*(4000/200) -> 20 | F55: =E55*C55*0.18 -> 0 | G55: =F55*4300000 -> 0 | H55: =(4300000*5/25)*F55 -> 0 | I55: =(4300000*10/25)*F55 -> 0 | J55: =F55*2580000 -> 0 | K55: =F55*3440000 -> 0
A56: 7 | B56: March | D56: 0 | E56: =1*(4000/200) -> 20 | F56: =E56*C56*0.18 -> 0 | G56: =F56*4300000 -> 0 | H56: =(4300000*5/25)*F56 -> 0 | I56: =(4300000*10/25)*F56 -> 0 | J56: =F56*2580000 -> 0 | K56: =F56*3440000 -> 0
A57: 8 | B57: March | C57: 0.0045 | D57: 0.49555733 | E57: =1*(4000/200) -> 20 | F57: =E57*C57*0.18 -> 0.0162 | G57: =F57*4300000 -> 69660 | H57: =(4300000*5/25)*F57 -> 13932 | I57: =(4300000*10/25)*F57 -> 27864 | J57: =F57*2580000 -> 41796 | K57: =F57*3440000 -> 55728
A58: 9 | B58: March | C58: 0.068 | D58: 7.4884219 | E58: =1*(4000/200) -> 20 | F58: =E58*C58*0.18 -> 0.2448 | G58: =F58*4300000 -> 1052640 | H58: =(4300000*5/25)*F58 -> 210528 | I58: =(4300000*10/25)*F58 -> 421056 | J58: =F58*2580000 -> 631584 | K58: =F58*3440000 -> 842112
A59: 10 | B59: March | C59: 0.211 | D59: 23.236133 | E59: =1*(4000/200) -> 20 | F59: =E59*C59*0.18 -> 0.7596 | G59: =F59*4300000 -> 3266280 | H59: =(4300000*5/25)*F59 -> 653256 | I59: =(4300000*10/25)*F59 -> 1306512 | J59: =F59*2580000 -> 1959768 | K59: =F59*3440000 -> 2613024
A60: 11 | B60: March | C60: 0.398 | D60: 43.829293 | E60: =1*(4000/200) -> 20 | F60: =E60*C60*0.18 -> 1.4328 | G60: =F60*4300000 -> 6161040 | H60: =(4300000*5/25)*F60 -> 1232208 | I60: =(4300000*10/25)*F60 -> 2464416 | J60: =F60*2580000 -> 3696624 | K60: =F60*3440000 -> 4928832
A61: 12 | B61: March | C61: 0.531 | D61: 58.475765 | E61: =1*(4000/200) -> 20 | F61: =E61*C61*0.18 -> 1.9116 | G61: =F61*4300000 -> 8219880 | H61: =(4300000*5/25)*F61 -> 1643976 | I61: =(4300000*10/25)*F61 -> 3287952 | J61: =F61*2580000 -> 4931928 | K61: =F61*3440000 -> 6575904
A62: 13 | B62: March | C62: 0.608 | D62: 66.955302 | E62: =1*(4000/200) -> 20 | F62: =E62*C62*0.18 -> 2.1888 | G62: =F62*4300000 -> 9411840 | H62: =(4300000*5/25)*F62 -> 1882368 | I62: =(4300000*10/25)*F62 -> 3764736 | J62: =F62*2580000 -> 5647104 | K62: =F62*3440000 -> 7529472
A63: 14 | B63: March | C63: 0.653 | D63: 71.910875 | E63: =1*(4000/200) -> 20 | F63: =E63*C63*0.18 -> 2.3508 | G63: =F63*4300000 -> 10108440 | H63: =(4300000*5/25)*F63 -> 2021688 | I63: =(4300000*10/25)*F63 -> 4043376 | J63: =F63*2580000 -> 6065064 | K63: =F63*3440000 -> 8086752
A64: 15 | B64: March | C64: 0.621 | D64: 68.386912 | E64: =1*(4000/200) -> 20 | F64: =E64*C64*0.18 -> 2.2356 | G64: =F64*4300000 -> 9613080 | H64: =(4300000*5/25)*F64 -> 1922616 | I64: =(4300000*10/25)*F64 -> 3845232 | J64: =F64*2580000 -> 5767848 | K64: =F64*3440000 -> 7690464
A65: 16 | B65: March | C65: 0.541 | D65: 59.577004 | E65: =1*(4000/200) -> 20 | F65: =E65*C65*0.18 -> 1.9476 | G65: =F65*4300000 -> 8374680 | H65: =(4300000*5/25)*F65 -> 1674936 | I65: =(4300000*10/25)*F65 -> 3349872 | J65: =F65*2580000 -> 5024808 | K65: =F65*3440000 -> 6699744
A66: 17 | B66: March | C66: 0.418 | D66: 46.03177 | E66: =1*(4000/200) -> 20 | F66: =E66*C66*0.18 -> 1.5048 | G66: =F66*4300000 -> 6470640 | H66: =(4300000*5/25)*F66 -> 1294128 | I66: =(4300000*10/25)*F66 -> 2588256 | J66: =F66*2580000 -> 3882384 | K66: =F66*3440000 -> 5176512
A67: 18 | B67: March | C67: 0.261 | D67: 28.742325 | E67: =1*(4000/200) -> 20 | F67: =E67*C67*0.18 -> 0.9396 | G67: =F67*4300000 -> 4040280 | H67: =(4300000*5/25)*F67 -> 808056 | I67: =(4300000*10/25)*F67 -> 1616112 | J67: =F67*2580000 -> 2424168 | K67: =F67*3440000 -> 3232224
A68: 19 | B68: March | C68: 0.096 | D68: 10.57189 | E68: =1*(4000/200) -> 20 | F68: =E68*C68*0.18 -> 0.3456 | G68: =F68*4300000 -> 1486080 | H68: =(4300000*5/25)*F68 -> 297216 | I68: =(4300000*10/25)*F68 -> 594432 | J68: =F68*2580000 -> 891648 | K68: =F68*3440000 -> 1188864
A69: 20 | B69: March | C69: 0.008 | D69: 0.88099082 | E69: =1*(4000/200) -> 20 | F69: =E69*C69*0.18 -> 0.0288 | G69: =F69*4300000 -> 123840 | H69: =(4300000*5/25)*F69 -> 24768 | I69: =(4300000*10/25)*F69 -> 49536 | J69: =F69*2580000 -> 74304 | K69: =F69*3440000 -> 99072
A70: 21 | B70: March | D70: 0 | E70: =1*(4000/200) -> 20 | F70: =E70*C70*0.18 -> 0 | G70: =F70*4300000 -> 0 | H70: =(4300000*5/25)*F70 -> 0 | I70: =(4300000*10/25)*F70 -> 0 | J70: =F70*2580000 -> 0 | K70: =F70*3440000 -> 0
...

Sheet System Load
A1: Whole Year | B1: Hours | C1: Load_Shape | D1: Hourly Demand per household | I1: Area: | J1: Version2_GR_Prosumers Residential | O1: 20.7 TWh at 2022
A2: January: Hr 1 | B2: 31 | C2: 0.23097 | D2: =($O$2*C2)/100 -> 0.37062628 | I2: Yearly Shape: | J2: System Load | O2: =(20.7*(10^9))/(30*4300000) -> 160.46512
A3: January: Hr 2 | B3: 31 | C3: 0.23 | D3: =($O$2*C3)/100 -> 0.36906977 | I3: Profile Type: | J3: Energy Load Shape (% of annual energy)
A4: January: Hr 3 | B4: 31 | C4: 0.23 | D4: =($O$2*C4)/100 -> 0.36906977
A5: January: Hr 4 | B5: 31 | C5: 0.23 | D5: =($O$2*C5)/100 -> 0.36906977
A6: January: Hr 5 | B6: 31 | C6: 0.23 | D6: =($O$2*C6)/100 -> 0.36906977
A7: January: Hr 6 | B7: 31 | C7: 0.31 | D7: =($O$2*C7)/100 -> 0.49744186
A8: January: Hr 7 | B8: 31 | C8: 0.52 | D8: =($O$2*C8)/100 -> 0.8344186
A9: January: Hr 8 | B9: 31 | C9: 0.52 | D9: =($O$2*C9)/100 -> 0.8344186
A10: January: Hr 9 | B10: 31 | C10: 0.51 | D10: =($O$2*C10)/100 -> 0.81837209
A11: January: Hr 10 | B11: 31 | C11: 0.31 | D11: =($O$2*C11)/100 -> 0.49744186
A12: January: Hr 11 | B12: 31 | C12: 0.31 | D12: =($O$2*C12)/100 -> 0.49744186
A13: January: Hr 12 | B13: 31 | C13: 0.31 | D13: =($O$2*C13)/100 -> 0.49744186
A14: January: Hr 13 | B14: 31 | C14: 0.31 | D14: =($O$2*C14)/100 -> 0.49744186
A15: January: Hr 14 | B15: 31 | C15: 0.31 | D15: =($O$2*C15)/100 -> 0.49744186
... A289: December: Hr 24 | B289: 31 | C289: 0.2 | D289: =($O$2*C289)/100 -> 0.32093023
D290: =SUM(D2:D289) -> 160.46667
D291: =D290*30 -> 4814.0002

Sheet Battery_Storage
A1: Hour_Index | B1: Battery_Charge_kWh | C1: Battery_Discharge_kWh | D1: SOC_kWh | E1: willigness to self consume γs (prosumer price dependant) | F1: willigness to consume from Grid γs (spot price dependant) | G1: Spot Price | H1: =MAX(G2:G289) -> 369.17 | I1: =MIN(G2:G289) -> 59.27 | M1: MIN charge | N1: MAX charge | R1: Battery_Charge_kWh | S1: Generated from Pv kwh | T1: household Demand Kwh | U1: Surplus/Deficit (Kwh) | V1: Export to Grid Kwh from PV | W1: Utility function based on Grid | X1: Utility based on PV | Z1: Charge or Sell to grid | AA1: Buy from Grid or import from Discharge | AB1: income | AC1: payment | AD1: expences at current regime | AF1: Surplus/Deficit cumulative
A2: 1 | B2: =D2 -> 1.2 | C2: 0 | D2: =M5*0.1 -> 1.2 | E2: =1*(1/(G2+0.01))^1.1 -> 0.0025131186 | G2: 230.9 | H2: =G2/($H$1-$I$1) -> 0.74507906 | M2: 0.1 | N2: 0.9 | R2: =S2-T2-V2 -> #VALUE! | S2: ='Solar Availability and Gener GR'!F2 -> 0 | T2: 0.29721721 | U2: =S2-T2 -> -0.29721721 | V2: =IF(U2<0,"Buy from Grid","sell the surplus or charge") -> Buy from Grid | W2: =(1*(1/(G2+0.01))^1.1)*(LN(T2+1)) -> 0.00065396714 | AA2: =IF(D2+AF2>0,"discharge","buy from the Grid") -> discharge | AD2: =(T2*G2)/1000 -> 0.068627454 | AF2: =U2 -> -0.29721721
A3: 2 | C3: =-U3 -> 0.29596899 | D3: =(D2)+(B3*0.8)-(C3/0.8) -> 0.83003876 | E3: =1*(1/(G3+0.01))^1.1 -> 0.0021315491 | G3: 268.19 | H3: =G3/($H$1-$I$1) -> 0.8654082 | R3: =S3-T3-V3 -> #VALUE! | S3: ='Solar Availability and Gener GR'!F3 -> 0 | T3: 0.29596899 | U3: =S3-T3 -> -0.29596899 | V3: =IF(U3<0,"Buy from Grid","sell the surplus or charge") -> Buy from Grid | W3: =(1*(1/(G3+0.01))^1.1)*(LN(T3+1)) -> 0.0005526226 | AA3: =IF(D3+AF3>0,"discharge","buy from the Grid") -> discharge | AD3: =(T3*G3)/1000 -> 0.079375924 | AF3: =U3+AF2 -> -0.5931862
A4: 3 | C4: 0 | D4: =(D3)+(B4*0.8)-(C4/0.8) -> 0.83003876 | E4: =1*(1/(G4+0.01))^1.1 -> 0.0025290169 | G4: 229.58 | H4: =G4/($H$1-$I$1) -> 0.74081962 | M4: 10 kwh | N4: 5 kw | O4: per house | P4: n=90% | R4: =S4-T4-V4 -> #VALUE! | S4: ='Solar Availability and Gener GR'!F4 -> 0 | T4: 0.29596899 | U4: =S4-T4 -> -0.29596899 | V4: =IF(U4<0,"Buy from Grid","sell the surplus or charge") -> Buy from Grid | W4: =(1*(1/(G4+0.01))^1.1)*(LN(T4+1)) -> 0.00065566957 | AA4: =IF(D4+AF4>0,"discharge","buy from the Grid") -> buy from the Grid | AC4: =(U4*G4)/1000 -> -0.067948561 | AD4: =(T4*G4)/1000 -> 0.067948561 | AF4: =U4+AF3 -> -0.88915519
A5: 4 | C5: 0 | D5: =(D4)+(B5*0.8)-(C5/0.8) -> 0.83003876 | E5: =1*(1/(G5+0.01))^1.1 -> 0.002453675 | G5: 235.98 | H5: =G5/($H$1-$I$1) -> 0.76147144 | M5: 12 | R5: =S5-T5-V5 -> #VALUE! | S5: ='Solar Availability and Gener GR'!F5 -> 0 | T5: 0.29596899 | U5: =S5-T5 -> -0.29596899 | V5: =IF(U5<0,"Buy from Grid","sell the surplus or charge") -> Buy from Grid | W5: =(1*(1/(G5+0.01))^1.1)*(LN(T5+1)) -> 0.00063613652 | AA5: =IF(D5+AF5>0,"discharge","buy from the Grid") -> buy from the Grid | AC5: =(U5*G5)/1000 -> -0.069842763 | AD5: =(T5*G5)/1000 -> 0.069842763 | AF5: =U5+AF4 -> -1.1851242
A6: 5 | C6: 0 | D6: =(D5)+(B6*0.8)-(C6/0.8) -> 0.83003876 | E6: =1*(1/(G6+0.01))^1.1 -> 0.0024732663 | G6: 234.28 | H6: =G6/($H$1-$I$1) -> 0.7559858 | O6: 4kw | P6: pv | R6: =S6-T6-V6 -> #VALUE! | S6: ='Solar Availability and Gener GR'!F6 -> 0 | T6: 0.29596899 | U6: =S6-T6 -> -0.29596899 | V6: =IF(U6<0,"Buy from Grid","sell the surplus or charge") -> Buy from Grid | W6: =(1*(1/(G6+0.01))^1.1)*(LN(T6+1)) -> 0.00064121573 | AA6: =IF(D6+AF6>0,"discharge","buy from the Grid") -> buy from the Grid | AC6: =(U6*G6)/1000 -> -0.069339616 | AD6: =(T6*G6)/1000 -> 0.069339616 | AF6: =U6+AF5 -> -1.4810932
A7: 6 | C7: 0 | D7: =(D6)+(B7*0.8)-(C7/0.8) -> 0.83003876 | E7: =1*(1/(G7+0.01))^1.1 -> 0.0024349413 | G7: 237.63 | H7: =G7/($H$1-$I$1) -> 0.76679574 | R7: =S7-T7-V7 -> #VALUE! | S7: ='Solar Availability and Gener GR'!F7 -> 0 | T7: 0.39891473 | U7: =S7-T7 -> -0.39891473 | V7: =IF(U7<0,"Buy from Grid","sell the surplus or charge") -> Buy from Grid | W7: =(1*(1/(G7+0.01))^1.1)*(LN(T7+1)) -> 0.00081740187 | AA7: =IF(D7+AF7>0,"discharge","buy from the Grid") -> buy from the Grid | AC7: =(U7*G7)/1000 -> -0.094794107 | AD7: =(T7*G7)/1000 -> 0.094794107 | AF7: =U7+AF6 -> -1.8800079
A8: 7 | C8: 0 | D8: =(D7)+(B8*0.8)-(C8/0.8) -> 0.83003876 | E8: =1*(1/(G8+0.01))^1.1 -> 0.0024122647 | G8: 239.66 | H8: =G8/($H$1-$I$1) -> 0.77334624 | R8: =S8-T8-V8 -> #VALUE! | S8: ='Solar Availability and Gener GR'!F8 -> 0.036 | T8: 0.66914729 | U8: =S8-T8 -> -0.63314729 | V8: =IF(U8<0,"Buy from Grid","sell the surplus or charge") -> Buy from Grid | W8: =(1*(1/(G8+0.01))^1.1)*(LN(T8+1)) -> 0.0012358343 | AA8: =IF(D8+AF8>0,"discharge","buy from the Grid") -> buy from the Grid | AC8: =(U8*G8)/1000 -> -0.15174008 | AD8: =(T8*G8)/1000 -> 0.16036784 | AF8: =U8+AF7 -> -2.5131552
A9: 8 | C9: 0 | D9: =(D8)+(B9*0.8)-(C9/0.8) -> 0.83003876 | E9: =1*(1/(G9+0.01))^1.1 -> 0.0025014382 | G9: 231.88 | H9: =G9/($H$1-$I$1) -> 0.74824137 | R9: =S9-T9-V9 -> #VALUE! | S9: ='Solar Availability and Gener GR'!F9 -> 0.072 | T9: 0.66914729 | U9: =S9-T9 -> -0.59714729 | V9: =IF(U9<0,"Buy from Grid","sell the surplus or charge") -> Buy from Grid | W9: =(1*(1/(G9+0.01))^1.1)*(LN(T9+1)) -> 0.001281519 | AA9: =IF(D9+AF9>0,"discharge","buy from the Grid") -> buy from the Grid | AC9: =(U9*G9)/1000 -> -0.13846651 | AD9: =(T9*G9)/1000 -> 0.15516187 | AF9: =U9+AF8 -> -3.1103025
A10: 9 | C10: 0 | D10: =(D9)+(B10*0.8)-(C10/0.8) -> 0.83003876 | E10: =1*(1/(G10+0.01))^1.1 -> 0.0031791024 | G10: 186.47 | H10: =G10/($H$1-$I$1) -> 0.60171023 | R10: =S10-T10-V10 -> #VALUE! | S10: ='Solar Availability and Gener GR'!F10 -> 0.108 | T10: 0.65627907 | U10: =S10-T10 -> -0.54827907 | V10: =IF(U10<0,"Buy from Grid","sell the surplus or charge") -> Buy from Grid | W10: =(1*(1/(G10+0.01))^1.1)*(LN(T10+1)) -> 0.001604091 | AA10: =IF(D10+AF10>0,"discharge","buy from the Grid") -> buy from the Grid | AC10: =(U10*G10)/1000 -> -0.1022376 | AD10: =(T10*G10)/1000 -> 0.12237636 | AF10: =U10+AF9 -> -3.6585816
A11: 10 | C11: 0 | D11: =(D10)+(B11*0.8)-(C11/0.8) -> 0.83003876 | E11: =1*(1/(G11+0.01))^1.1 -> 0.0031791024 | G11: 186.47 | H11: =G11/($H$1-$I$1) -> 0.60171023 | R11: =S11-T11-V11 -> #VALUE! | S11: ='Solar Availability and Gener GR'!F11 -> 0.17817591 | T11: 0.39891473 | U11: =S11-T11 -> -0.22073882 | V11: =IF(U11<0,"Buy from Grid","sell the surplus or charge") -> Buy from Grid | W11: =(1*(1/(G11+0.01))^1.1)*(LN(T11+1)) -> 0.0010672143 | AA11: =IF(D11+AF11>0,"discharge","buy from the Grid") -> buy from the Grid | AC11: =(U11*G11)/1000 -> -0.041161167 | AD11: =(T11*G11)/1000 -> 0.074385629 | AF11: =U11+AF10 -> -3.8793204
A12: 11 | B12: =U12 -> 0.20969829 | D12: =(D11)+(B12*0.8)-(C12/0.8) -> 0.99779739 | E12: =1*(1/(G12+0.01))^1.1 -> 0.0033614618 | G12: 177.25 | H12: =G12/($H$1-$I$1) -> 0.5719587 | R12: =S12-T12-V12 -> #VALUE! | S12: ='Solar Availability and Gener GR'!F12 -> 0.60861302 | T12: 0.39891473 | U12: =S12-T12 -> 0.20969829 | V12: =IF(U12<0,"Buy from Grid","sell the surplus or charge") -> sell the surplus or charge | W12: =(1*(1/(G12+0.01))^1.1)*(LN(T12+1)) -> 0.0011284318 | X12: =(1*(1/(G12+0.01))^1.1)*(LN(S12+1)) -> 0.0015979459 | Y12: =X12/W12 -> 1.4160767 | Z12: =IF(Y12>=2,"sell to the Grid","charge") -> charge | AD12: =(T12*G12)/1000 -> 0.070707636 | AF12: =U12+AF11 -> -3.6696221
A13: 12 | D13: =(D12)+(B13*0.8)-(C13/0.8) -> 0.99779739 | E13: =1*(1/(G13+0.01))^1.1 -> 0.0035539536 | G13: 168.5 | H13: =G13/($H$1-$I$1) -> 0.54372378 | R13: =S13-T13-V13 -> #VALUE! | S13: ='Solar Availability and Gener GR'!F13 -> 1.0764 | T13: 0.39891473 | U13: =S13-T13 -> 0.67748527 | V13: =IF(U13<0,"Buy from Grid","sell the surplus or charge") -> sell the surplus or charge | W13: =(1*(1/(G13+0.01))^1.1)*(LN(T13+1)) -> 0.0011930506 | X13: =(1*(1/(G13+0.01))^1.1)*(LN(S13+1)) -> 0.0025966451 | Y13: =X13/W13 -> 2.1764752 | Z13: =IF(Y13>=2,"sell to the Grid","charge") -> sell to the Grid | AB13: =(U13*G13)/1000 -> 0.11415627 | AD13: =(T13*G13)/1000 -> 0.067217132 | AF13: =U13+AF12 -> -2.9921368
A14: 13 | D14: =(D13)+(B14*0.8)-(C14/0.8) -> 0.99779739 | E14: =1*(1/(G14+0.01))^1.1 -> 0.0075534485 | G14: 84.9 | H14: =G14/($H$1-$I$1) -> 0.27395934 | R14: =S14-T14-V14 -> #VALUE! | S14: ='Solar Availability and Gener GR'!F14 -> 1.3716 | T14: 0.39891473 | U14: =S14-T14 -> 0.97268527 | V14: =IF(U14<0,"Buy from Grid","sell the surplus or charge") -> sell the surplus or charge | W14: =(1*(1/(G14+0.01))^1.1)*(LN(T14+1)) -> 0.0025356681 | X14: =(1*(1/(G14+0.01))^1.1)*(LN(S14+1)) -> 0.0065228925 | Y14: =X14/W14 -> 2.5724552 | Z14: =IF(Y14>=2,"sell to the Grid","charge") -> sell to the Grid | AB14: =(U14*G14)/1000 -> 0.08258098 | AD14: =(T14*G14)/1000 -> 0.03386786 | AF14: =U14+AF13 -> -2.0194515
A15: 14 | D15: =(D14)+(B15*0.8)-(C15/0.8) -> 0.99779739 | E15: =1*(1/(G15+0.01))^1.1 -> 0.0078530408 | G15: 81.95 | H15: =G15/($H$1-$I$1) -> 0.26444014 | R15: =S15-T15-V15 -> #VALUE! | S15: ='Solar Availability and Gener GR'!F15 -> 1.4292 | T15: 0.39891473 | U15: =S15-T15 -> 1.0302853 | V15: =IF(U15<0,"Buy from Grid","sell the surplus or charge") -> sell the surplus or charge | W15: =(1*(1/(G15+0.01))^1.1)*(LN(T15+1)) -> 0.0026362402 | X15: =(1*(1/(G15+0.01))^1.1)*(LN(S15+1)) -> 0.0069700605 | Y15: =X15/W15 -> 2.6439398 | Z15: =IF(Y15>=2,"sell to the Grid","charge") -> sell to the Grid | AB15: =(U15*G15)/1000 -> 0.084431878 | AD15: =(T15*G15)/1000 -> 0.032691062 | AF15: =U15+AF14 -> -0.98916627
A16: 15 | D16: =(D15)+(B16*0.8)-(C16/0.8) -> 0.99779739 | E16: =1*(1/(G16+0.01))^1.1 -> 0.0033104786 | G16: 179.73 | H16: =G16/($H$1-$I$1) -> 0.57996128 | R16: =S16-T16-V16 -> #VALUE! | S16: ='Solar Availability and Gener GR'!F16 -> 1.3536 | T16: 0.39891473 | U16: =S16-T16 -> 0.95468527 | V16: =IF(U16<0,"Buy from Grid","sell the surplus or charge") -> sell the surplus or charge | W16: =(1*(1/(G16+0.01))^1.1)*(LN(T16+1)) -> 0.0011113169 | X16: =(1*(1/(G16+0.01))^1.1)*(LN(S16+1)) -> 0.0028335912 | Y16: =X16/W16 -> 2.5497598 | Z16: =IF(Y16>=2,"sell to the Grid","charge") -> sell to the Grid | AB16: =(U16*G16)/1000 -> 0.17158558 | AD16: =(T16*G16)/1000 -> 0.071696944 | AF16: =U16+AF15 -> -0.034480997
A17: 16 | D17: =(D16)+(B17*0.8)-(C17/0.8) -> 0.99779739 | E17: =1*(1/(G17+0.01))^1.1 -> 0.0019194623 | G17: 295 | H17: =G17/($H$1-$I$1) -> 0.95191997 | R17: =S17-T17-V17 -> #VALUE! | S17: ='Solar Availability and Gener GR'!F17 -> 1.1052 | T17: 0.39891473 | U17: =S17-T17 -> 0.70628527 | V17: =IF(U17<0,"Buy from Grid","sell the surplus or charge") -> sell the surplus or charge | W17: =(1*(1/(G17+0.01))^1.1)*(LN(T17+1)) -> 0.00064435724 | X17: =(1*(1/(G17+0.01))^1.1)*(LN(S17+1)) -> 0.0014288678 | Y17: =X17/W17 -> 2.2175088 | Z17: =IF(Y17>=2,"sell to the Grid","charge") -> sell to the Grid | AB17: =(U17*G17)/1000 -> 0.20835416 | AD17: =(T17*G17)/1000 -> 0.11767984 | AF17: =U17+AF16 -> 0.67180427
A18: 17 | B18: =U18 -> 0.36068527 | D18: =(D17)+(B18*0.8)-(C18/0.8) -> 1.2863456 | E18: =1*(1/(G18+0.01))^1.1 -> 0.0015997173 | G18: 348.15 | H18: =G18/($H$1-$I$1) -> 1.1234269 | R18: =S18-T18-V18 -> #VALUE! | S18: ='Solar Availability and Gener GR'!F18 -> 0.7596 | T18: 0.39891473 | U18: =S18-T18 -> 0.36068527 | V18: =IF(U18<0,"Buy from Grid","sell the surplus or charge") -> sell the surplus or charge | W18: =(1*(1/(G18+0.01))^1.1)*(LN(T18+1)) -> 0.00053701988 | X18: =(1*(1/(G18+0.01))^1.1)*(LN(S18+1)) -> 0.00090397866 | Y18: =X18/W18 -> 1.6833244 | Z18: =IF(Y18>=2,"sell to the Grid","charge") -> charge | AD18: =(T18*G18)/1000 -> 0.13888216 | AF18: =U18+AF17 -> 1.0324895
A19: 18 | C19: 0 | D19: =(D18)+(B19*0.8)-(C19/0.8) -> 1.2863456 | E19: =1*(1/(G19+0.01))^1.1 -> 0.0017411635 | G19: 322.34 | H19: =G19/($H$1-$I$1) -> 1.040142 | R19: =S19-T19-V19 -> #VALUE! | S19: ='Solar Availability and Gener GR'!F19 -> 0.3096 | T19: 0.66914729 | U19: =S19-T19 -> -0.35954729 | V19: =IF(U19<0,"Buy from Grid","sell the surplus or charge") -> Buy from Grid | W19: =(1*(1/(G19+0.01))^1.1)*(LN(T19+1)) -> 0.00089202051 | AA19: =IF(D19+AF19>0,"discharge","buy from the Grid") -> discharge | AD19: =(T19*G19)/1000 -> 0.21569294 | AF19: =U19+AF18 -> 0.67294226
A20: 19 | C20: 0 | D20: =(D19)+(B20*0.8)-(C20/0.8) -> 1.2863456 | E20: =1*(1/(G20+0.01))^1.1 -> 0.0018729686 | G20: 301.65 | H20: =G20/($H$1-$I$1) -> 0.97337851 | R20: =S20-T20-V20 -> #VALUE! | S20: ='Solar Availability and Gener GR'!F20 -> 0.0288 | T20: 0.65627907 | U20: =S20-T20 -> -0.62747907 | V20: =IF(U20<0,"Buy from Grid","sell the surplus or charge") -> Buy from Grid | W20: =(1*(1/(G20+0.01))^1.1)*(LN(T20+1)) -> 0.00094505045 | AA20: =IF(D20+AF20>0,"discharge","buy from the Grid") -> discharge | AD20: =(T20*G20)/1000 -> 0.19796658 | AF20: =U20+AF19 -> 0.045463189
A21: 20 | C21: 0 | D21: =(D20)+(B21*0.8)-(C21/0.8) -> 1.2863456 | E21: =1*(1/(G21+0.01))^1.1 -> 0.0015748215 | G21: 353.15 | H21: =G21/($H$1-$I$1) -> 1.1395611 | R21: =S21-T21-V21 -> #VALUE! | S21: ='Solar Availability and Gener GR'!F21 -> 0 | T21: 0.66914729 | U21: =S21-T21 -> -0.66914729 | V21: =IF(U21<0,"Buy from Grid","sell the surplus or charge") -> Buy from Grid | W21: =(1*(1/(G21+0.01))^1.1)*(LN(T21+1)) -> 0.00080680136 | AA21: =IF(D21+AF21>0,"discharge","buy from the Grid") -> discharge | AD21: =(T21*G21)/1000 -> 0.23630936 | AF21: =U21+AF20 -> -0.6236841
A22: 21 | C22: 0 | D22: =(D21)+(B22*0.8)-(C22/0.8) -> 1.2863456 | E22: =1*(1/(G22+0.01))^1.1 -> 0.0015271869 | G22: 363.15 | H22: =G22/($H$1-$I$1) -> 1.1718296 | R22: =S22-T22-V22 -> #VALUE! | S22: ='Solar Availability and Gener GR'!F22 -> 0 | T22: 0.66914729 | U22: =S22-T22 -> -0.66914729 | V22: =IF(U22<0,"Buy from Grid","sell the surplus or charge") -> Buy from Grid | W22: =(1*(1/(G22+0.01))^1.1)*(LN(T22+1)) -> 0.00078239754 | AA22: =IF(D22+AF22>0,"discharge","buy from the Grid") -> buy from the Grid | AC22: =(U22*G22)/1000 -> -0.24300084 | AD22: =(T22*G22)/1000 -> 0.24300084 | AF22: =U22+AF21 -> -1.2928314
A23: 22 | C23: 0 | D23: =(D22)+(B23*0.8)-(C23/0.8) -> 1.2863456 | E23: =1*(1/(G23+0.01))^1.1 -> 0.0020048122 | G23: 283.56 | H23: =G23/($H$1-$I$1) -> 0.91500484 | R23: =S23-T23-V23 -> #VALUE! | S23: ='Solar Availability and Gener GR'!F23 -> 0 | T23: 0.39891473 | U23: =S23-T23 -> -0.39891473 | V23: =IF(U23<0,"Buy from Grid","sell the surplus or charge") -> Buy from Grid | W23: =(1*(1/(G23+0.01))^1.1)*(LN(T23+1)) -> 0.00067300891 | AA23: =IF(D23+AF23>0,"discharge","buy from the Grid") -> buy from the Grid | AC23: =(U23*G23)/1000 -> -0.11311626 | AD23: =(T23*G23)/1000 -> 0.11311626 | AF23: =U23+AF22 -> -1.6917461
A24: 23 | C24: 0 | D24: =(D23)+(B24*0.8)-(C24/0.8) -> 1.2863456 | E24: =1*(1/(G24+0.01))^1.1 -> 0.0024311149 | G24: 237.97 | H24: =G24/($H$1-$I$1) -> 0.76789287 | R24: =S24-T24-V24 -> #VALUE! | S24: ='Solar Availability and Gener GR'!F24 -> 0 | T24: 0.39891473 | U24: =S24-T24 -> -0.39891473 | V24: =IF(U24<0,"Buy from Grid","sell the surplus or charge") -> Buy from Grid | W24: =(1*(1/(G24+0.01))^1.1)*(LN(T24+1)) -> 0.00081611737 | AA24: =IF(D24+AF24>0,"discharge","buy from the Grid") -> buy from the Grid | AC24: =(U24*G24)/1000 -> -0.094929738 | AD24: =(T24*G24)/1000 -> 0.094929738 | AF24: =U24+AF23 -> -2.0906608
A25: 24 | C25: 0 | D25: =(D24)+(B25*0.8)-(C25/0.8) -> 1.2863456 | E25: =1*(1/(G25+0.01))^1.1 -> 0.0025168351 | G25: 230.59 | H25: =G25/($H$1-$I$1) -> 0.74407874 | R25: =S25-T25-V25 -> #VALUE! | S25: ='Solar Availability and Gener GR'!F25 -> 0 | T25: 0.39891473 | U25: =S25-T25 -> -0.39891473 | V25: =IF(U25<0,"Buy from Grid","sell the surplus or charge") -> Buy from Grid | W25: =(1*(1/(G25+0.01))^1.1)*(LN(T25+1)) -> 0.00084489335 | AA25: =IF(D25+AF25>0,"discharge","buy from the Grid") -> buy from the Grid | AC25: =(U25*G25)/1000 -> -0.091985747 | AD25: =(T25*G25)/1000 -> 0.091985747 | AF25: =U25+AF24 -> -2.4895756
A26: 25 | C26: 0 | D26: =(D25)+(B26*0.8)-(C26/0.8) -> 1.2863456 | E26: =1*(1/(G26+0.01))^1.1 -> 0.0031641675 | G26: 187.27 | H26: =G26/($H$1-$I$1) -> 0.60429171 | R26: =S26-T26-V26 -> #VALUE! | S26: ='Solar Availability and Gener GR'!F26 -> 0 | T26: 0.29596899 | U26: =S26-T26 -> -0.29596899 | V26: =IF(U26<0,"Buy from Grid","sell the surplus or charge") -> Buy from Grid | W26: =(1*(1/(G26+0.01))^1.1)*(LN(T26+1)) -> 0.00082033785 | AA26: =IF(D26+AF26>0,"discharge","buy from the Grid") -> buy from the Grid | AC26: =(U26*G26)/1000 -> -0.055426113 | AD26: =(T26*G26)/1000 -> 0.055426113 | AF26: =U26+AF25 -> -2.7855446
A27: 26 | C27: 0 | D27: =(D26)+(B27*0.8)-(C27/0.8) -> 1.2863456 | E27: =1*(1/(G27+0.01))^1.1 -> 0.0031654689 | G27: 187.2 | H27: =G27/($H$1-$I$1) -> 0.60406583 | R27: =S27-T27-V27 -> #VALUE! | S27: ='Solar Availability and Gener GR'!F27 -> 0 | T27: 0.29596899 | U27: =S27-T27 -> -0.29596899 | V27: =IF(U27<0,"Buy from Grid","sell the surplus or charge") -> Buy from Grid | W27: =(1*(1/(G27+0.01))^1.1)*(LN(T27+1)) -> 0.00082067527 | AA27: =IF(D27+AF27>0,"discharge","buy from the Grid") -> buy from the Grid | AC27: =(U27*G27)/1000 -> -0.055405395 | AD27: =(T27*G27)/1000 -> 0.055405395 | AF27: =U27+AF26 -> -3.0815136
A28: 27 | C28: 0 | D28: =(D27)+(B28*0.8)-(C28/0.8) -> 1.2863456 | E28: =1*(1/(G28+0.01))^1.1 -> 0.0033050171 | G28: 180 | H28: =G28/($H$1-$I$1) -> 0.58083253 | R28: =S28-T28-V28 -> #VALUE! | S28: ='Solar Availability and Gener GR'!F28 -> 0 | T28: 0.29596899 | U28: =S28-T28 -> -0.29596899 | V28: =IF(U28<0,"Buy from Grid","sell the surplus or charge") -> Buy from Grid | W28: =(1*(1/(G28+0.01))^1.1)*(LN(T28+1)) -> 0.00085685433 | AA28: =IF(D28+AF28>0,"discharge","buy from the Grid") -> buy from the Grid | AC28: =(U28*G28)/1000 -> -0.053274419 | AD28: =(T28*G28)/1000 -> 0.053274419 | AF28: =U28+AF27 -> -3.3774825
A29: 28 | C29: 0 | D29: =(D28)+(B29*0.8)-(C29/0.8) -> 1.2863456 | E29: =1*(1/(G29+0.01))^1.1 -> 0.0033050171 | G29: 180 | H29: =G29/($H$1-$I$1) -> 0.58083253 | R29: =S29-T29-V29 -> #VALUE! | S29: ='Solar Availability and Gener GR'!F29 -> 0 | T29: 0.29596899 | U29: =S29-T29 -> -0.29596899 | V29: =IF(U29<0,"Buy from Grid","sell the surplus or charge") -> Buy from Grid | W29: =(1*(1/(G29+0.01))^1.1)*(LN(T29+1)) -> 0.00085685433 | AA29: =IF(D29+AF29>0,"discharge","buy from the Grid") -> buy from the Grid | AC29: =(U29*G29)/1000 -> -0.053274419 | AD29: =(T29*G29)/1000 -> 0.053274419 | AF29: =U29+AF28 -> -3.6734515
A30: 29 | C30: 0 | D30: =(D29)+(B30*0.8)-(C30/0.8) -> 1.2863456 | E30: =1*(1/(G30+0.01))^1.1 -> 0.0031900146 | G30: 185.89 | H30: =G30/($H$1-$I$1) -> 0.59983866 | R30: =S30-T30-V30 -> #VALUE! | S30: ='Solar Availability and Gener GR'!F30 -> 0 | T30: 0.29596899 | U30: =S30-T30 -> -0.29596899 | V30: =IF(U30<0,"Buy from Grid","sell the surplus or charge") -> Buy from Grid | W30: =(1*(1/(G30+0.01))^1.1)*(LN(T30+1)) -> 0.00082703895 | AA30: =IF(D30+AF30>0,"discharge","buy from the Grid") -> buy from the Grid | AC30: =(U30*G30)/1000 -> -0.055017676 | AD30: =(T30*G30)/1000 -> 0.055017676 | AF30: =U30+AF29 -> -3.9694205
A31: 30 | C31: 0 | D31: =(D30)+(B31*0.8)-(C31/0.8) -> 1.2863456 | E31: =1*(1/(G31+0.01))^1.1 -> 0.0020998342 | G31: 271.87 | H31: =G31/($H$1-$I$1) -> 0.87728299 | R31: =S31-T31-V31 -> #VALUE! | S31: ='Solar Availability and Gener GR'!F31 -> 0 | T31: 0.39891473 | U31: =S31-T31 -> -0.39891473 | V31: =IF(U31<0,"Buy from Grid","sell the surplus or charge") -> Buy from Grid | W31: =(1*(1/(G31+0.01))^1.1)*(LN(T31+1)) -> 0.00070490751 | AA31: =IF(D31+AF31>0,"discharge","buy from the Grid") -> buy from the Grid | AC31: =(U31*G31)/1000 -> -0.10845295 | AD31: =(T31*G31)/1000 -> 0.10845295 | AF31: =U31+AF30 -> -4.3683353
A32: 31 | C32: 0 | D32: =(D31)+(B32*0.8)-(C32/0.8) -> 1.2863456 | E32: =1*(1/(G32+0.01))^1.1 -> 0.0015965895 | G32: 348.77 | H32: =G32/($H$1-$I$1) -> 1.1254276 | R32: =S32-T32-V32 -> #VALUE! | S32: ='Solar Availability and Gener GR'!F32 -> 0.036 | T32: 0.66914729 | U32: =S32-T32 -> -0.63314729 | V32: =IF(U32<0,"Buy from Grid","sell the surplus or charge") -> Buy from Grid | W32: =(1*(1/(G32+0.01))^1.1)*(LN(T32+1)) -> 0.00081795338 | AA32: =IF(D32+AF32>0,"discharge","buy from the Grid") -> buy from the Grid | AC32: =(U32*G32)/1000 -> -0.22082278 | AD32: =(T32*G32)/1000 -> 0.2333785 | AF32: =U32+AF31 -> -5.0014825
A33: 32 | C33: 0 | D33: =(D32)+(B33*0.8)-(C33/0.8) -> 1.2863456 | E33: =1*(1/(G33+0.01))^1.1 -> 0.0015717859 | G33: 353.77 | H33: =G33/($H$1-$I$1) -> 1.1415618 | R33: =S33-T33-V33 -> #VALUE! | S33: ='Solar Availability and Gener GR'!F33 -> 0.072 | T33: 0.65627907 | U33: =S33-T33 -> -0.58427907 | V33: =IF(U33<0,"Buy from Grid","sell the surplus or charge") -> Buy from Grid | W33: =(1*(1/(G33+0.01))^1.1)*(LN(T33+1)) -> 0.00079308162 | AA33: =IF(D33+AF33>0,"discharge","buy from the Grid") -> buy from the Grid | AC33: =(U33*G33)/1000 -> -0.20670041 | AD33: =(T33*G33)/1000 -> 0.23217185 | AF33: =U33+AF32 -> -5.5857616
... A35: 34 | C35: 0 | D35: =(D34)+(B35*0.8)-(C35/0.8) -> 1.2863456 | E35: =1*(1/(G35+0.01))^1.1 -> 0.002880095 | G35: 203.99 | H35: =G35/($H$1-$I$1) -> 0.6582446 | R35: =S35-T35-V35 -> #VALUE! | S35: ='Solar Availability and Gener GR'!F35 -> 0.17817591 | T35: 0.39891473 | U35: =S35-T35 -> -0.22073882 | V35: =IF(U35<0,"Buy from Grid","sell the surplus or charge") -> Buy from Grid | W35: =(1*(1/(G35+0.01))^1.1)*(LN(T35+1)) -> 0.00096683851 | AA35: =IF(D35+AF35>0,"discharge","buy from the Grid") -> buy from the Grid | AC35: =(U35*G35)/1000 -> -0.045028512 | AD35: =(T35*G35)/1000 -> 0.081374616 | AF35: =U35+AF34 -> -6.3547795
A36: 35 | B36: =U36 -> 0.20969829 | D36: =(D35)+(B36*0.8)-(C36/0.8) -> 1.4541042 | E36: =1*(1/(G36+0.01))^1.1 -> 0.0030056175 | G36: 196.23 | H36: =G36/($H$1-$I$1) -> 0.63320426 | R36: =S36-T36-V36 -> #VALUE! | S36: ='Solar Availability and Gener GR'!F36 -> 0.60861302 | T36: 0.39891473 | U36: =S36-T36 -> 0.20969829 | V36: =IF(U36<0,"Buy from Grid","sell the surplus or charge") -> sell the surplus or charge | W36: =(1*(1/(G36+0.01))^1.1)*(LN(T36+1)) -> 0.001008976 | X36: =(1*(1/(G36+0.01))^1.1)*(LN(S36+1)) -> 0.0014287874 | Y36: =X36/W36 -> 1.4160767 | Z36: =IF(Y36>=2,"sell to the Grid","charge") -> charge | AD36: =(T36*G36)/1000 -> 0.078279037 | AF36: =U36+AF35 -> -6.1450812
A37: 36 | D37: =(D36)+(B37*0.8)-(C37/0.8) -> 1.4541042 | E37: =1*(1/(G37+0.01))^1.1 -> 0.0031343309 | G37: 188.89 | H37: =G37/($H$1-$I$1) -> 0.6095192 | R37: =S37-T37-V37 -> #VALUE! | S37: ='Solar Availability and Gener GR'!F37 -> 1.0764 | T37: 0.39891473 | U37: =S37-T37 -> 0.67748527 | V37: =IF(U37<0,"Buy from Grid","sell the surplus or charge") -> sell the surplus or charge | W37: =(1*(1/(G37+0.01))^1.1)*(LN(T37+1)) -> 0.0010521847 | X37: =(1*(1/(G37+0.01))^1.1)*(LN(S37+1)) -> 0.0022900538 | Y37: =X37/W37 -> 2.1764752 | Z37: =IF(Y37>=2,"sell to the Grid","charge") -> sell to the Grid | AB37: =(U37*G37)/1000 -> 0.12797019 | AD37: =(T37*G37)/1000 -> 0.075351003 | AF37: =U37+AF36 -> -5.4675959
A38: 37 | D38: =(D37)+(B38*0.8)-(C38/0.8) -> 1.4541042 | E38: =1*(1/(G38+0.01))^1.1 -> 0.0031523156 | G38: 187.91 | H38: =G38/($H$1-$I$1) -> 0.60635689 | R38: =S38-T38-V38 -> #VALUE! | S38: ='Solar Availability and Gener GR'!F38 -> 1.6416 | T38: 0.39891473 | U38: =S38-T38 -> 1.2426853 | V38: =IF(U38<0,"Buy from Grid","sell the surplus or charge") -> sell the surplus or charge | W38: =(1*(1/(G38+0.01))^1.1)*(LN(T38+1)) -> 0.0010582221 | X38: =(1*(1/(G38+0.01))^1.1)*(LN(S38+1)) -> 0.0030621115 | Y38: =X38/W38 -> 2.8936378 | Z38: =IF(Y38>=2,"sell to the Grid","charge") -> sell to the Grid | AB38: =(U38*G38)/1000 -> 0.23351299 | AD38: =(T38*G38)/1000 -> 0.074960067 | AF38: =U38+AF37 -> -4.2249107
A39: 38 | D39: =(D38)+(B39*0.8)-(C39/0.8) -> 1.4541042 | E39: =1*(1/(G39+0.01))^1.1 -> 0.0031343309 | G39: 188.89 | H39: =G39/($H$1-$I$1) -> 0.6095192 | R39: =S39-T39-V39 -> #VALUE! | S39: ='Solar Availability and Gener GR'!F39 -> 1.7748 | T39: 0.39891473 | U39: =S39-T39 -> 1.3758853 | V39: =IF(U39<0,"Buy from Grid","sell the surplus or charge") -> sell the surplus or charge | W39: =(1*(1/(G39+0.01))^1.1)*(LN(T39+1)) -> 0.0010521847 | X39: =(1*(1/(G39+0.01))^1.1)*(LN(S39+1)) -> 0.0031988313 | Y39: =X39/W39 -> 3.0401804 | Z39: =IF(Y39>=2,"sell to the Grid","charge") -> sell to the Grid | AB39: =(U39*G39)/1000 -> 0.25989097 | AD39: =(T39*G39)/1000 -> 0.075351003 | AF39: =U39+AF38 -> -2.8490254
A40: 39 | D40: =(D39)+(B40*0.8)-(C40/0.8) -> 1.4541042 | E40: =1*(1/(G40+0.01))^1.1 -> 0.0028846054 | G40: 203.7 | H40: =G40/($H$1-$I$1) -> 0.65730881 | R40: =S40-T40-V40 -> #VALUE! | S40: ='Solar Availability and Gener GR'!F40 -> 1.6596 | T40: 0.39891473 | U40: =S40-T40 -> 1.2606853 | V40: =IF(U40<0,"Buy from Grid","sell the surplus or charge") -> sell the surplus or charge | W40: =(1*(1/(G40+0.01))^1.1)*(LN(T40+1)) -> 0.00096835264 | X40: =(1*(1/(G40+0.01))^1.1)*(LN(S40+1)) -> 0.002821651 | Y40: =X40/W40 -> 2.9138672 | Z40: =IF(Y40>=2,"sell to the Grid","charge") -> sell to the Grid | AB40: =(U40*G40)/1000 -> 0.25680159 | AD40: =(T40*G40)/1000 -> 0.08125893 | AF40: =U40+AF39 -> -1.5883401
A41: 40 | D41: =(D40)+(B41*0.8)-(C41/0.8) -> 1.4541042 | E41: =1*(1/(G41+0.01))^1.1 -> 0.001524324 | G41: 363.77 | H41: =G41/($H$1-$I$1) -> 1.1738303 | R41: =S41-T41-V41 -> #VALUE! | S41: ='Solar Availability and Gener GR'!F41 -> 1.4112 | T41: 0.39891473 | U41: =S41-T41 -> 1.0122853 | V41: =IF(U41<0,"Buy from Grid","sell the surplus or charge") -> sell the surplus or charge | W41: =(1*(1/(G41+0.01))^1.1)*(LN(T41+1)) -> 0.00051171062 | X41: =(1*(1/(G41+0.01))^1.1)*(LN(S41+1)) -> 0.001341595 | Y41: =X41/W41 -> 2.6217846 | Z41: =IF(Y41>=2,"sell to the Grid","charge") -> sell to the Grid | AB41: =(U41*G41)/1000 -> 0.36823901 | AD41: =(T41*G41)/1000 -> 0.14511321 | AF41: =U41+AF40 -> -0.57605486
...

Sheet Sheet2
A1: =MAX(A3:A182) -> 0.0037648538
A3: 0.00065396714
A4: 0.0005526226
A5: 0.00065566957
A6: 0.00063613652
A7: 0.00064121573
A8: 0.00081740187
A9: 0.0012358343
A10: 0.001281519
A11: 0.001604091
A12: 0.0010672143
A13: 0.00089202051
A14: 0.00094505045
... A182: 0.00079318304

Sheet Daily Demand per household
A1: 16.6 | B1: 18 | C1: 20 | D1: 22 | E1: 24 | F1: 26 | G1: 28 | H1: Annual Demand (TWh)
A2: 2022 | B2: 2025 | C2: 2030 | D2: 2035 | E2: 2040 | F2: 2045 | G2: 2050 | H2: Year
A3: =A1*10^9/(30*4300000) -> 128.68217 | B3: =B1*10^9/(30*4300000) -> 139.53488 | C3: =C1*10^9/(30*4300000) -> 155.03876 | D3: =D1*10^9/(30*4300000) -> 170.54264 | E3: =E1*10^9/(30*4300000) -> 186.04651 | F3: =F1*10^9/(30*4300000) -> 201.55039 | G3: =G1*10^9/(30*4300000) -> 217.05426 | H3: Daily Demand per household (KWh)

Sheet Utility Function plus20%
A1: Hour_Index | B1: Battery_Charge_kWh | C1: Battery_Discharge_kWh | D1: SOC_kWh | E1: Spot Price | F1: MIN charge | G1: MAX charge | K1: Generated from Pv kwh | L1: household Demand Kwh | M1: Surplus/Deficit (Kwh) | N1: Export to Grid Kwh from PV | O1: SC,min | P1: α, sc,opt | Q1: P,sell | R1: Utility based on PV, opt | S1: Utility based on PV, min | T1: Calculated Spot Price with Upv,min and a,sc,opt | U1: Charge or Sell to grid | V1: Buy from Grid or import from Discharge | W1: income | X1: payment | Y1: expences at current regime | AA1: Surplus/Deficit cumulative | AC1: Consumption from Grid | AD1: C+SC
A2: 1 | B2: =D2 -> 1.2 | C2: 0 | D2: =F5*0.1 -> 1.2 | E2: 230.9 | F2: 0.1 | G2: 0.9 | K2: ='Solar Availability and Gener GR'!F2 -> 0 | L2: ='System Load'!D2 -> 0.37062628 | M2: =K2-L2 -> -0.37062628 | N2: =IF(M2<0,"Buy from Grid","sell the surplus or charge") -> Buy from Grid | V2: =IF(D2+M2>0,"discharge","buy from the Grid") -> discharge | Y2: =(L2*E2)/1000 -> 0.085577608 | AA2: =M2 -> -0.37062628 | AD2: =AC2+O2 -> 0
A3: 2 | B3: =IF(U3="charge",Q3,0) -> 0 | C3: =IF(V2="discharge",M3,0) -> -0.36906977 | D3: =(D2)+(B3*0.8)+(C3/0.8) -> 0.73866279 | E3: 268.19 | K3: ='Solar Availability and Gener GR'!F3 -> 0 | L3: ='System Load'!D3 -> 0.36906977 | M3: =K3-L3 -> -0.36906977 | N3: =IF(M3<0,"Buy from Grid","sell the surplus or charge") -> Buy from Grid | V3: =IF(D3+M3>0,"discharge","buy from the Grid") -> discharge | Y3: =(L3*E3)/1000 -> 0.098980821 | AA3: =M3+AA2 -> -0.73969605 | AD3: =AC3+O3 -> 0
A4: 3 | B4: =IF(U4="charge",Q4,0) -> 0 | C4: =IF(V3="discharge",M4,0) -> -0.36906977 | D4: =(D3)+(B4*0.8)+(C4/0.8) -> 0.27732558 | E4: 229.58 | F4: 10 kwh | G4: 5 kw | H4: per house | I4: n=90% | K4: ='Solar Availability and Gener GR'!F4 -> 0 | L4: ='System Load'!D4 -> 0.36906977 | M4: =K4-L4 -> -0.36906977 | N4: =IF(M4<0,"Buy from Grid","sell the surplus or charge") -> Buy from Grid | V4: =IF(D4+M4>0,"discharge","buy from the Grid") -> buy from the Grid | Y4: =(L4*E4)/1000 -> 0.084731037 | AA4: =M4+AA3 -> -1.1087658 | AD4: =AC4+O4 -> 0
A5: 4 | B5: =IF(U5="charge",Q5,0) -> 0 | C5: =IF(V4="discharge",M5,0) -> 0 | D5: =(D4)+(B5*0.8)+(C5/0.8) -> 0.27732558 | E5: 235.98 | F5: 12 | K5: ='Solar Availability and Gener GR'!F5 -> 0 | L5: ='System Load'!D5 -> 0.36906977 | M5: =K5-L5 -> -0.36906977 | N5: =IF(M5<0,"Buy from Grid","sell the surplus or charge") -> Buy from Grid | V5: =IF(D5+M5>0,"discharge","buy from the Grid") -> buy from the Grid | X5: =(M5*E5)/1000 -> -0.087093084 | Y5: =(L5*E5)/1000 -> 0.087093084 | AA5: =M5+AA4 -> -1.4778356 | AC5: =L5 -> 0.36906977 | AD5: =AC5+O5 -> 0.36906977
A6: 5 | B6: =IF(U6="charge",Q6,0) -> 0 | C6: =IF(V5="discharge",M6,0) -> 0 | D6: =(D5)+(B6*0.8)+(C6/0.8) -> 0.27732558 | E6: 234.28 | H6: 4kw | I6: pv | K6: ='Solar Availability and Gener GR'!F6 -> 0 | L6: ='System Load'!D6 -> 0.36906977 | M6: =K6-L6 -> -0.36906977 | N6: =IF(M6<0,"Buy from Grid","sell the surplus or charge") -> Buy from Grid | V6: =IF(D6+M6>0,"discharge","buy from the Grid") -> buy from the Grid | X6: =(M6*E6)/1000 -> -0.086465665 | Y6: =(L6*E6)/1000 -> 0.086465665 | AA6: =M6+AA5 -> -1.8469053 | AC6: =L6 -> 0.36906977 | AD6: =AC6+O6 -> 0.36906977
A7: 6 | B7: =IF(U7="charge",Q7,0) -> 0 | C7: =IF(V6="discharge",M7,0) -> 0 | D7: =(D6)+(B7*0.8)+(C7/0.8) -> 0.27732558 | E7: 237.63 | K7: ='Solar Availability and Gener GR'!F7 -> 0 | L7: ='System Load'!D7 -> 0.49744186 | M7: =K7-L7 -> -0.49744186 | N7: =IF(M7<0,"Buy from Grid","sell the surplus or charge") -> Buy from Grid | V7: =IF(D7+M7>0,"discharge","buy from the Grid") -> buy from the Grid | X7: =(M7*E7)/1000 -> -0.11820711 | Y7: =(L7*E7)/1000 -> 0.11820711 | AA7: =M7+AA6 -> -2.3443472 | AC7: =L7 -> 0.49744186 | AD7: =AC7+O7 -> 0.49744186
A8: 7 | B8: =IF(U8="charge",Q8,0) -> 0 | C8: =IF(V7="discharge",M8,0) -> 0 | D8: =(D7)+(B8*0.8)+(C8/0.8) -> 0.27732558 | E8: 239.66 | K8: ='Solar Availability and Gener GR'!F8 -> 0.036 | L8: ='System Load'!D8 -> 0.8344186 | M8: =K8-L8 -> -0.7984186 | N8: =IF(M8<0,"Buy from Grid","sell the surplus or charge") -> Buy from Grid | V8: =IF(D8+M8>0,"discharge","buy from the Grid") -> buy from the Grid | X8: =(M8*E8)/1000 -> -0.191349 | Y8: =(L8*E8)/1000 -> 0.19997676 | AA8: =M8+AA7 -> -3.1427658 | AC8: =L8 -> 0.8344186 | AD8: =AC8+O8 -> 0.8344186
A9: 8 | B9: =IF(U9="charge",Q9,0) -> 0 | C9: =IF(V8="discharge",M9,0) -> 0 | D9: =(D8)+(B9*0.8)+(C9/0.8) -> 0.27732558 | E9: 231.88 | K9: ='Solar Availability and Gener GR'!F9 -> 0.072 | L9: ='System Load'!D9 -> 0.8344186 | M9: =K9-L9 -> -0.7624186 | N9: =IF(M9<0,"Buy from Grid","sell the surplus or charge") -> Buy from Grid | V9: =IF(D9+M9>0,"discharge","buy from the Grid") -> buy from the Grid | X9: =(M9*E9)/1000 -> -0.17678963 | Y9: =(L9*E9)/1000 -> 0.19348499 | AA9: =M9+AA8 -> -3.9051844 | AC9: =L9 -> 0.8344186 | AD9: =AC9+O9 -> 0.8344186
A10: 9 | B10: =IF(U10="charge",Q10,0) -> 0 | C10: =IF(V9="discharge",M10,0) -> 0 | D10: =(D9)+(B10*0.8)+(C10/0.8) -> 0.27732558 | E10: 186.47 | K10: ='Solar Availability and Gener GR'!F10 -> 0.108 | L10: ='System Load'!D10 -> 0.81837209 | M10: =K10-L10 -> -0.71037209 | N10: =IF(M10<0,"Buy from Grid","sell the surplus or charge") -> Buy from Grid | V10: =IF(D10+M10>0,"discharge","buy from the Grid") -> buy from the Grid | X10: =(M10*E10)/1000 -> -0.13246308 | Y10: =(L10*E10)/1000 -> 0.15260184 | AA10: =M10+AA9 -> -4.6155565 | AC10: =L10 -> 0.81837209 | AD10: =AC10+O10 -> 0.81837209
A11: 10 | B11: =IF(U11="charge",Q11,0) -> 0 | C11: =IF(V10="discharge",M11,0) -> 0 | D11: =(D10)+(B11*0.8)+(C11/0.8) -> 0.27732558 | E11: 186.47 | K11: ='Solar Availability and Gener GR'!F11 -> 0.17817591 | L11: ='System Load'!D11 -> 0.49744186 | M11: =K11-L11 -> -0.31926595 | N11: =IF(M11<0,"Buy from Grid","sell the surplus or charge") -> Buy from Grid | V11: =IF(D11+M11>0,"discharge","buy from the Grid") -> buy from the Grid | X11: =(M11*E11)/1000 -> -0.059533522 | Y11: =(L11*E11)/1000 -> 0.092757984 | AA11: =M11+AA10 -> -4.9348225 | AC11: =L11 -> 0.49744186 | AD11: =AC11+O11 -> 0.49744186
A12: 11 | B12: =IF(U12="charge",Q12,0) -> 0 | C12: =IF(V11="discharge",M12,0) -> 0 | D12: =(D11)+(B12*0.8)+(C12/0.8) -> 0.27732558 | E12: 177.25 | K12: ='Solar Availability and Gener GR'!F12 -> 0.60861302 | L12: ='System Load'!D12 -> 0.49744186 | M12: =K12-L12 -> 0.11117115 | N12: =IF(M12<0,"Buy from Grid","sell the surplus or charge") -> sell the surplus or charge | O12: 0.25 | P12: =0.25/L12 -> 0.50257129 | Q12: =K12-P12*L12 -> 0.35861302 | R12: =((1/(E12+0.01))*LN(0.25))+(E12*(K12-0.25)) -> 63.556336 | S12: =((1/(E12+0.01))*LN(L12))+(E12*(K12-L12)) -> 19.701148 | T12: =(S12+((S12^2)-4*(K12-L12*P12)*LN(L12*P12))^(0.5))/(2*(K12-L12*P12)) -> 55.007345 | U12: =IF(E12>=T12*1.2,"sell to the Grid","charge") -> sell to the Grid | W12: =(Q12*E12)/1000 -> 0.063564157 | Y12: =(L12*E12)/1000 -> 0.08817157 | AA12: =M12+AA11 -> -4.8236513 | AD12: =AC12+O12 -> 0.25
A13: 12 | B13: =IF(U13="charge",Q13,0) -> 0 | C13: =IF(V12="discharge",M13,0) -> 0 | D13: =(D12)+(B13*0.8)+(C13/0.8) -> 0.27732558 | E13: 168.5 | K13: ='Solar Availability and Gener GR'!F13 -> 1.0764 | L13: ='System Load'!D13 -> 0.49744186 | M13: =K13-L13 -> 0.57895814 | N13: =IF(M13<0,"Buy from Grid","sell the surplus or charge") -> sell the surplus or charge | O13: 0.25 | P13: =0.25/L13 -> 0.50257129 | Q13: =K13-P13*L13 -> 0.8264 | R13: =((1/(E13+0.01))*LN(0.25))+(E13*(K13-0.25)) -> 139.24017 | S13: =((1/(E13+0.01))*LN(L13))+(E13*(K13-L13)) -> 97.550303 | T13: =(S13+((S13^2)-4*(K13-L13*P13)*LN(L13*P13))^(0.5))/(2*(K13-L13*P13)) -> 118.05669 | U13: =IF(E13>=T13*1.2,"sell to the Grid","charge") -> sell to the Grid | W13: =(Q13*E13)/1000 -> 0.1392484 | Y13: =(L13*E13)/1000 -> 0.083818953 | AA13: =M13+AA12 -> -4.2446932 | AD13: =AC13+O13 -> 0.25
A14: 13 | B14: =IF(U14="charge",Q14,0) -> 0 | C14: =IF(V13="discharge",M14,0) -> 0 | D14: =(D13)+(B14*0.8)+(C14/0.8) -> 0.27732558 | E14: 84.9 | K14: ='Solar Availability and Gener GR'!F14 -> 1.3716 | L14: ='System Load'!D14 -> 0.49744186 | M14: =K14-L14 -> 0.87415814 | N14: =IF(M14<0,"Buy from Grid","sell the surplus or charge") -> sell the surplus or charge | O14: 0.25 | P14: =0.25/L14 -> 0.50257129 | Q14: =K14-P14*L14 -> 1.1216 | R14: =((1/(E14+0.01))*LN(0.25))+(E14*(K14-0.25)) -> 95.207513 | S14: =((1/(E14+0.01))*LN(L14))+(E14*(K14-L14)) -> 74.207802 | T14: =(S14+((S14^2)-4*(K14-L14*P14)*LN(L14*P14))^(0.5))/(2*(K14-L14*P14)) -> 66.181125 | U14: =IF(E14>=T14*1.2,"sell to the Grid","charge") -> sell to the Grid | Y14: =(L14*E14)/1000 -> 0.042232814 | AA14: =M14+AA13 -> -3.370535 | AD14: =AC14+O14 -> 0.25
A15: 14 | B15: =IF(U15="charge",Q15,0) -> 0 | C15: =IF(V14="discharge",M15,0) -> 0 | D15: =(D14)+(B15*0.8)+(C15/0.8) -> 0.27732558 | E15: 81.95 | K15: ='Solar Availability and Gener GR'!F15 -> 1.4292 | L15: ='System Load'!D15 -> 0.49744186 | M15: =K15-L15 -> 0.93175814 | N15: =IF(M15<0,"Buy from Grid","sell the surplus or charge") -> sell the surplus or charge | O15: 0.25 | P15: =0.25/L15 -> 0.50257129 | Q15: =K15-P15*L15 -> 1.1792 | R15: =((1/(E15+0.01))*LN(0.25))+(E15*(K15-0.25)) -> 96.618526 | S15: =((1/(E15+0.01))*LN(L15))+(E15*(K15-L15)) -> 76.34906 | T15: =(S15+((S15^2)-4*(K15-L15*P15)*LN(L15*P15))^(0.5))/(2*(K15-L15*P15)) -> 64.764641 | U15: =IF(E15>=T15*1.2,"sell to the Grid","charge") -> sell to the Grid | Y15: =(L15*E15)/1000 -> 0.04076536 | AA15: =M15+AA14 -> -2.4387769 | AD15: =AC15+O15 -> 0.25
A16: 15 | B16: =IF(U16="charge",Q16,0) -> 0 | C16: =IF(V15="discharge",M16,0) -> 0 | D16: =(D15)+(B16*0.8)+(C16/0.8) -> 0.27732558 | E16: 179.73 | K16: ='Solar Availability and Gener GR'!F16 -> 1.3536 | L16: ='System Load'!D16 -> 0.49744186 | M16: =K16-L16 -> 0.85615814 | N16: =IF(M16<0,"Buy from Grid","sell the surplus or charge") -> sell the surplus or charge | O16: 0.25 | P16: =0.25/L16 -> 0.50257129 | Q16: =K16-P16*L16 -> 1.1036 | R16: =((1/(E16+0.01))*LN(0.25))+(E16*(K16-0.25)) -> 198.34232 | S16: =((1/(E16+0.01))*LN(L16))+(E16*(K16-L16)) -> 153.87342 | T16: =(S16+((S16^2)-4*(K16-L16*P16)*LN(L16*P16))^(0.5))/(2*(K16-L16*P16)) -> 139.43762 | U16: =IF(E16>=T16*1.2,"sell to the Grid","charge") -> sell to the Grid | Y16: =(L16*E16)/1000 -> 0.089405226 | AA16: =M16+AA15 -> -1.5826187 | AD16: =AC16+O16 -> 0.25
A17: 16 | B17: =IF(U17="charge",Q17,0) -> 0 | C17: =IF(V16="discharge",M17,0) -> 0 | D17: =(D16)+(B17*0.8)+(C17/0.8) -> 0.27732558 | E17: 295 | K17: ='Solar Availability and Gener GR'!F17 -> 1.1052 | L17: ='System Load'!D17 -> 0.49744186 | M17: =K17-L17 -> 0.60775814 | N17: =IF(M17<0,"Buy from Grid","sell the surplus or charge") -> sell the surplus or charge | O17: 0.25 | P17: =0.25/L17 -> 0.50257129 | Q17: =K17-P17*L17 -> 0.8552 | R17: =((1/(E17+0.01))*LN(0.25))+(E17*(K17-0.25)) -> 252.2793 | S17: =((1/(E17+0.01))*LN(L17))+(E17*(K17-L17)) -> 179.28628 | T17: =(S17+((S17^2)-4*(K17-L17*P17)*LN(L17*P17))^(0.5))/(2*(K17-L17*P17)) -> 209.65025 | U17: =IF(E17>=T17*1.2,"sell to the Grid","charge") -> sell to the Grid | W17: =(Q17*E17)/1000 -> 0.252284 | Y17: =(L17*E17)/1000 -> 0.14674535 | AA17: =M17+AA16 -> -0.97486061 | AD17: =AC17+O17 -> 0.25
A18: 17 | B18: =IF(U18="charge",Q18,0) -> 0 | C18: =IF(V17="discharge",M18,0) -> 0 | D18: =(D17)+(B18*0.8)+(C18/0.8) -> 0.27732558 | E18: 348.15 | K18: ='Solar Availability and Gener GR'!F18 -> 0.7596 | L18: ='System Load'!D18 -> 0.49744186 | M18: =K18-L18 -> 0.26215814 | N18: =IF(M18<0,"Buy from Grid","sell the surplus or charge") -> sell the surplus or charge | O18: 0.25 | P18: =0.25/L18 -> 0.50257129 | Q18: =K18-P18*L18 -> 0.5096 | R18: =((1/(E18+0.01))*LN(0.25))+(E18*(K18-0.25)) -> 177.41326 | S18: =((1/(E18+0.01))*LN(L18))+(E18*(K18-L18)) -> 91.268351 | T18: =(S18+((S18^2)-4*(K18-L18*P18)*LN(L18*P18))^(0.5))/(2*(K18-L18*P18)) -> 179.11321 | U18: =IF(E18>=T18*1.2,"sell to the Grid","charge") -> sell to the Grid | W18: =(Q18*E18)/1000 -> 0.17741724 | Y18: =(L18*E18)/1000 -> 0.17318438 | AA18: =M18+AA17 -> -0.71270247 | AD18: =AC18+O18 -> 0.25
A19: 18 | B19: =IF(U19="charge",Q19,0) -> 0 | C19: =IF(V18="discharge",M19,0) -> 0 | D19: =(D18)+(B19*0.8)+(C19/0.8) -> 0.27732558 | E19: 322.34 | K19: ='Solar Availability and Gener GR'!F19 -> 0.3096 | L19: ='System Load'!D19 -> 0.8344186 | M19: =K19-L19 -> -0.5248186 | N19: =IF(M19<0,"Buy from Grid","sell the surplus or charge") -> Buy from Grid | V19: =IF(D19+M19>0,"discharge","buy from the Grid") -> buy from the Grid | Y19: =(L19*E19)/1000 -> 0.26896649 | AA19: =M19+AA18 -> -1.2375211 | AD19: =AC19+O19 -> 0
A20: 19 | B20: =IF(U20="charge",Q20,0) -> 0 | C20: =IF(V19="discharge",M20,0) -> 0 | D20: =(D19)+(B20*0.8)+(C20/0.8) -> 0.27732558 | E20: 301.65 | K20: ='Solar Availability and Gener GR'!F20 -> 0.0288 | L20: ='System Load'!D20 -> 0.81837209 | M20: =K20-L20 -> -0.78957209 | N20: =IF(M20<0,"Buy from Grid","sell the surplus or charge") -> Buy from Grid | V20: =IF(D20+M20>0,"discharge","buy from the Grid") -> buy from the Grid | Y20: =(L20*E20)/1000 -> 0.24686194 | AA20: =M20+AA19 -> -2.0270932 | AD20: =AC20+O20 -> 0
A21: 20 | B21: =IF(U21="charge",Q21,0) -> 0 | C21: =IF(V20="discharge",M21,0) -> 0 | D21: =(D20)+(B21*0.8)+(C21/0.8) -> 0.27732558 | E21: 353.15 | K21: ='Solar Availability and Gener GR'!F21 -> 0 | L21: ='System Load'!D21 -> 0.8344186 | M21: =K21-L21 -> -0.8344186 | N21: =IF(M21<0,"Buy from Grid","sell the surplus or charge") -> Buy from Grid | V21: =IF(D21+M21>0,"discharge","buy from the Grid") -> buy from the Grid | Y21: =(L21*E21)/1000 -> 0.29467493 | AA21: =M21+AA20 -> -2.8615118 | AD21: =AC21+O21 -> 0
A22: 21 | B22: =IF(U22="charge",Q22,0) -> 0 | C22: =IF(V21="discharge",M22,0) -> 0 | D22: =(D21)+(B22*0.8)+(C22/0.8) -> 0.27732558 | E22: 363.15 | K22: ='Solar Availability and Gener GR'!F22 -> 0 | L22: ='System Load'!D22 -> 0.8344186 | M22: =K22-L22 -> -0.8344186 | N22: =IF(M22<0,"Buy from Grid","sell the surplus or charge") -> Buy from Grid | V22: =IF(D22+M22>0,"discharge","buy from the Grid") -> buy from the Grid | X22: =(M22*E22)/1000 -> -0.30301912 | Y22: =(L22*E22)/1000 -> 0.30301912 | AA22: =M22+AA21 -> -3.6959304 | AC22: =L22 -> 0.8344186 | AD22: =AC22+O22 -> 0.8344186
A23: 22 | B23: =IF(U23="charge",Q23,0) -> 0 | C23: =IF(V22="discharge",M23,0) -> 0 | D23: =(D22)+(B23*0.8)+(C23/0.8) -> 0.27732558 | E23: 283.56 | K23: ='Solar Availability and Gener GR'!F23 -> 0 | L23: ='System Load'!D23 -> 0.49744186 | M23: =K23-L23 -> -0.49744186 | N23: =IF(M23<0,"Buy from Grid","sell the surplus or charge") -> Buy from Grid | V23: =IF(D23+M23>0,"discharge","buy from the Grid") -> buy from the Grid | X23: =(M23*E23)/1000 -> -0.14105461 | Y23: =(L23*E23)/1000 -> 0.14105461 | AA23: =M23+AA22 -> -4.1933722 | AC23: =L23 -> 0.49744186 | AD23: =AC23+O23 -> 0.49744186
A24: 23 | B24: =IF(U24="charge",Q24,0) -> 0 | C24: =IF(V23="discharge",M24,0) -> 0 | D24: =(D23)+(B24*0.8)+(C24/0.8) -> 0.27732558 | E24: 237.97 | K24: ='Solar Availability and Gener GR'!F24 -> 0 | L24: ='System Load'!D24 -> 0.49744186 | M24: =K24-L24 -> -0.49744186 | N24: =IF(M24<0,"Buy from Grid","sell the surplus or charge") -> Buy from Grid | V24: =IF(D24+M24>0,"discharge","buy from the Grid") -> buy from the Grid | X24: =(M24*E24)/1000 -> -0.11837624 | Y24: =(L24*E24)/1000 -> 0.11837624 | AA24: =M24+AA23 -> -4.6908141 | AC24: =L24 -> 0.49744186 | AD24: =AC24+O24 -> 0.49744186
A25: 24 | B25: =IF(U25="charge",Q25,0) -> 0 | C25: =IF(V24="discharge",M25,0) -> 0 | D25: =(D24)+(B25*0.8)+(C25/0.8) -> 0.27732558 | E25: 230.59 | K25: ='Solar Availability and Gener GR'!F25 -> 0 | L25: ='System Load'!D25 -> 0.49744186 | M25: =K25-L25 -> -0.49744186 | N25: =IF(M25<0,"Buy from Grid","sell the surplus or charge") -> Buy from Grid | V25: =IF(D25+M25>0,"discharge","buy from the Grid") -> buy from the Grid | X25: =(M25*E25)/1000 -> -0.11470512 | Y25: =(L25*E25)/1000 -> 0.11470512 | AA25: =M25+AA24 -> -5.188256 | AC25: =L25 -> 0.49744186 | AD25: =AC25+O25 -> 0.49744186
A26: 25 | B26: =IF(U26="charge",Q26,0) -> 0 | C26: =IF(V25="discharge",M26,0) -> 0 | D26: =(D25)+(B26*0.8)+(C26/0.8) -> 0.27732558 | E26: 187.27 | K26: ='Solar Availability and Gener GR'!F26 -> 0 | L26: ='System Load'!D26 -> 0.36906977 | M26: =K26-L26 -> -0.36906977 | N26: =IF(M26<0,"Buy from Grid","sell the surplus or charge") -> Buy from Grid | V26: =IF(D26+M26>0,"discharge","buy from the Grid") -> buy from the Grid | Y26: =(L26*E26)/1000 -> 0.069115695 | AA26: =M26+AA25 -> -5.5573257 | AD26: =AC26+O26 -> 0
A27: 26 | B27: =IF(U27="charge",Q27,0) -> 0 | C27: =IF(V26="discharge",M27,0) -> 0 | D27: =(D26)+(B27*0.8)+(C27/0.8) -> 0.27732558 | E27: 187.2 | K27: ='Solar Availability and Gener GR'!F27 -> 0 | L27: ='System Load'!D27 -> 0.36906977 | M27: =K27-L27 -> -0.36906977 | N27: =IF(M27<0,"Buy from Grid","sell the surplus or charge") -> Buy from Grid | V27: =IF(D27+M27>0,"discharge","buy from the Grid") -> buy from the Grid | X27: =(M27*E27)/1000 -> -0.06908986 | Y27: =(L27*E27)/1000 -> 0.06908986 | AA27: =M27+AA26 -> -5.9263955 | AC27: =L27 -> 0.36906977 | AD27: =AC27+O27 -> 0.36906977
A28: 27 | B28: =IF(U28="charge",Q28,0) -> 0 | C28: =IF(V27="discharge",M28,0) -> 0 | D28: =(D27)+(B28*0.8)+(C28/0.8) -> 0.27732558 | E28: 180 | K28: ='Solar Availability and Gener GR'!F28 -> 0 | L28: ='System Load'!D28 -> 0.36906977 | M28: =K28-L28 -> -0.36906977 | N28: =IF(M28<0,"Buy from Grid","sell the surplus or charge") -> Buy from Grid | V28: =IF(D28+M28>0,"discharge","buy from the Grid") -> buy from the Grid | X28: =(M28*E28)/1000 -> -0.066432558 | Y28: =(L28*E28)/1000 -> 0.066432558 | AA28: =M28+AA27 -> -6.2954653 | AC28: =L28 -> 0.36906977 | AD28: =AC28+O28 -> 0.36906977
A29: 28 | B29: =IF(U29="charge",Q29,0) -> 0 | C29: =IF(V28="discharge",M29,0) -> 0 | D29: =(D28)+(B29*0.8)+(C29/0.8) -> 0.27732558 | E29: 180 | K29: ='Solar Availability and Gener GR'!F29 -> 0 | L29: ='System Load'!D29 -> 0.36906977 | M29: =K29-L29 -> -0.36906977 | N29: =IF(M29<0,"Buy from Grid","sell the surplus or charge") -> Buy from Grid | V29: =IF(D29+M29>0,"discharge","buy from the Grid") -> buy from the Grid | X29: =(M29*E29)/1000 -> -0.066432558 | Y29: =(L29*E29)/1000 -> 0.066432558 | AA29: =M29+AA28 -> -6.664535 | AC29: =L29 -> 0.36906977 | AD29: =AC29+O29 -> 0.36906977
A30: 29 | B30: =IF(U30="charge",Q30,0) -> 0 | C30: =IF(V29="discharge",M30,0) -> 0 | D30: =(D29)+(B30*0.8)+(C30/0.8) -> 0.27732558 | E30: 185.89 | K30: ='Solar Availability and Gener GR'!F30 -> 0 | L30: ='System Load'!D30 -> 0.36906977 | M30: =K30-L30 -> -0.36906977 | N30: =IF(M30<0,"Buy from Grid","sell the surplus or charge") -> Buy from Grid | V30: =IF(D30+M30>0,"discharge","buy from the Grid") -> buy from the Grid | X30: =(M30*E30)/1000 -> -0.068606379 | Y30: =(L30*E30)/1000 -> 0.068606379 | AA30: =M30+AA29 -> -7.0336048 | AC30: =L30 -> 0.36906977 | AD30: =AC30+O30 -> 0.36906977
A31: 30 | B31: =IF(U31="charge",Q31,0) -> 0 | C31: =IF(V30="discharge",M31,0) -> 0 | D31: =(D30)+(B31*0.8)+(C31/0.8) -> 0.27732558 | E31: 271.87 | K31: ='Solar Availability and Gener GR'!F31 -> 0 | L31: ='System Load'!D31 -> 0.49744186 | M31: =K31-L31 -> -0.49744186 | N31: =IF(M31<0,"Buy from Grid","sell the surplus or charge") -> Buy from Grid | V31: =IF(D31+M31>0,"discharge","buy from the Grid") -> buy from the Grid | X31: =(M31*E31)/1000 -> -0.13523952 | Y31: =(L31*E31)/1000 -> 0.13523952 | AA31: =M31+AA30 -> -7.5310467 | AC31: =L31 -> 0.49744186 | AD31: =AC31+O31 -> 0.49744186
A32: 31 | B32: =IF(U32="charge",Q32,0) -> 0 | C32: =IF(V31="discharge",M32,0) -> 0 | D32: =(D31)+(B32*0.8)+(C32/0.8) -> 0.27732558 | E32: 348.77 | K32: ='Solar Availability and Gener GR'!F32 -> 0.036 | L32: ='System Load'!D32 -> 0.8344186 | M32: =K32-L32 -> -0.7984186 | N32: =IF(M32<0,"Buy from Grid","sell the surplus or charge") -> Buy from Grid | V32: =IF(D32+M32>0,"discharge","buy from the Grid") -> buy from the Grid | X32: =(M32*E32)/1000 -> -0.27846446 | Y32: =(L32*E32)/1000 -> 0.29102018 | AA32: =M32+AA31 -> -8.3294653 | AC32: =L32 -> 0.8344186 | AD32: =AC32+O32 -> 0.8344186
A33: 32 | B33: =IF(U33="charge",Q33,0) -> 0 | C33: =IF(V32="discharge",M33,0) -> 0 | D33: =(D32)+(B33*0.8)+(C33/0.8) -> 0.27732558 | E33: 353.77 | K33: ='Solar Availability and Gener GR'!F33 -> 0.072 | L33: ='System Load'!D33 -> 0.81837209 | M33: =K33-L33 -> -0.74637209 | N33: =IF(M33<0,"Buy from Grid","sell the surplus or charge") -> Buy from Grid | V33: =IF(D33+M33>0,"discharge","buy from the Grid") -> buy from the Grid | X33: =(M33*E33)/1000 -> -0.26404406 | Y33: =(L33*E33)/1000 -> 0.2895155 | AA33: =M33+AA32 -> -9.0758374 | AC33: =L33 -> 0.81837209 | AD33: =AC33+O33 -> 0.81837209
A34: 33 | B34: =IF(U34="charge",Q34,0) -> 0 | C34: =IF(V33="discharge",M34,0) -> 0 | D34: =(D33)+(B34*0.8)+(C34/0.8) -> 0.27732558 | E34: 231 | K34: ='Solar Availability and Gener GR'!F34 -> 0.108 | L34: ='System Load'!D34 -> 0.81837209 | M34: =K34-L34 -> -0.71037209 | N34: =IF(M34<0,"Buy from Grid","sell the surplus or charge") -> Buy from Grid | V34: =IF(D34+M34>0,"discharge","buy from the Grid") -> buy from the Grid | X34: =(M34*E34)/1000 -> -0.16409595 | Y34: =(L34*E34)/1000 -> 0.18904395 | AA34: =M34+AA33 -> -9.7862094 | AC34: =L34 -> 0.81837209 | AD34: =AC34+O34 -> 0.81837209
A35: 34 | B35: =IF(U35="charge",Q35,0) -> 0 | C35: =IF(V34="discharge",M35,0) -> 0 | D35: =(D34)+(B35*0.8)+(C35/0.8) -> 0.27732558 | E35: 203.99 | K35: ='Solar Availability and Gener GR'!F35 -> 0.17817591 | L35: ='System Load'!D35 -> 0.49744186 | M35: =K35-L35 -> -0.31926595 | N35: =IF(M35<0,"Buy from Grid","sell the surplus or charge") -> Buy from Grid | V35: =IF(D35+M35>0,"discharge","buy from the Grid") -> buy from the Grid | X35: =(M35*E35)/1000 -> -0.065127061 | Y35: =(L35*E35)/1000 -> 0.10147317 | AA35: =M35+AA34 -> -10.105475 | AC35: =L35 -> 0.49744186 | AD35: =AC35+O35 -> 0.49744186
